<!-- Cartpole Model - Here for reference only, this file has been heavily modified

    The state space is populated with joints in the order that they are
    defined in this file. The actuators also operate on joints.

    State-Space (name/joint/parameter):
        - cart      slider      position (m)
        - pole      hinge       angle (rad)
        - cart      slider      velocity (m/s)
        - pole      hinge       angular velocity (rad/s)

    Actuators (name/actuator/parameter):
        - cart      motor       force x (N)

-->
<mujoco model="wheelbot">
  <compiler coordinate="local" inertiafromgeom="true"/>

  <asset>
    <mesh name="leg_1" file="leg_1.obj" scale="0.001 0.001 0.001"/>
    <mesh name="leg_2" file="leg_2.obj" scale="0.001 0.001 0.001"/>
    <mesh name="wheel" file="wheel.obj" scale="0.001 0.001 0.001"/>
  </asset>

  <default>
    <geom contype="0" friction="1 0.1 0.1" rgba="0.7 0.7 0 1"/>
  </default>
  <option gravity="1e-5 0 -9.81" integrator="RK4" timestep="0.01"/>

  <worldbody>
    <geom name="ground" type="plane" pos="0 0 0" size="5 5 0.1" rgba="0.2 0.8 0.2 1" contype="1" conaffinity="1"/>
    <!-- Free base body -->
    <body name="base" pos="0 0 0.7">
      <joint name="free_joint" type="free"/>

      <!-- Geometry for visualization -->
      <geom type="box" density="604" size="0.14 0.2 0.065" rgba="0.8 0.3 0.3 1" contype="1" conaffinity="1"/>

      <body name="leg_1_l_1" pos="0.07 0.2 0" euler="90 180 -40">
        <!--<joint type="hinge" name="leg_1_l_1_h" axis="0 0 1" limited="true" range="-50 0"/>-->
        <geom type="mesh" mesh="leg_1" density="1" rgba="0.8 0.4 0.1 1" group="1"/>

        <body name="leg_2_l_1" pos="0 -0.28 0" euler="0 0 80">
          <joint type="hinge" axis="0 0 1"/>
          <geom type="mesh" mesh="leg_2" density="1" rgba="0.8 0.4 0.1 1" group="1"/>
          <site name="leg_2_l_1_s" pos="0 -0.407 0"/>

          <body name="wheel_l" pos="0 -0.407 0.02">
            <joint type="hinge" axis="0 0 1"/>
            <geom type="mesh" mesh="wheel" density="15" rgba="0.8 0.4 0.1 1" group="1"/>
          </body>
        </body>
      </body>

      <body name="leg_1_l_2" pos="-0.07 0.2 0" euler="90 180 40">
        <!--<joint type="hinge" name="leg_1_l_2_h" axis="0 0 1" limited="true" range="0 50"/>-->
        <geom type="mesh" mesh="leg_1" density="1" rgba="0.8 0.4 0.1 1" group="2"/>

        <body name="leg_2_l_2" pos="0 -0.28 0" euler="0 0 -80">
          <joint type="hinge" axis="0 0 1"/>
          <geom type="mesh" mesh="leg_2" density="1" rgba="0.8 0.4 0.1 1" group="2"/>
          <site name="leg_2_l_2_s" pos="0 -0.407 0"/>
        </body>
      </body>

      <body name="leg_1_r_1" pos="0.07 -0.2 0" euler="90 0 40">
        <!--<joint type="hinge" name="leg_1_r_1_h" axis="0 0 1" limited="true" range="0 50"/>-->
        <geom type="mesh" mesh="leg_1" density="1" rgba="0.8 0.4 0.1 1" group="3"/>

        <body name="leg_2_r_1" pos="0 -0.28 0" euler="0 0 -80">
          <joint type="hinge" axis="0 0 1"/>
          <geom type="mesh" mesh="leg_2" density="1" rgba="0.8 0.4 0.1 1" group="3"/>
          <site name="leg_2_r_1_s" pos="0 -0.407 0"/>

          <body name="wheel_r" pos="0 -0.407 0.02">
            <joint type="hinge" axis="0 0 1"/>
            <geom type="mesh" mesh="wheel" density="15" rgba="0.8 0.4 0.1 1" group="3"/>
          </body>
        </body>
      </body>

      <body name="leg_1_r_2" pos="-0.07 -0.2 0" euler="90 0 -40">
        <!--<joint type="hinge" name="leg_1_r_2_h" axis="0 0 1" limited="true" range="-50 0"/>-->
        <geom type="mesh" mesh="leg_1" density="1" rgba="0.8 0.4 0.1 1" group="4"/>

        <body name="leg_2_r_2" pos="0 -0.28 0" euler="0 0 80">
          <joint type="hinge" axis="0 0 1"/>
          <geom type="mesh" mesh="leg_2" density="1" rgba="0.8 0.4 0.1 1" group="4"/>
          <site name="leg_2_r_2_s" pos="0 -0.407 0"/>
        </body>
      </body>
    </body>
  </worldbody>

  <equality>
    <connect site1="leg_2_l_1_s" site2="leg_2_l_2_s" solimp="0.9999 0.9999 0.001 0.1 4"/>
    <connect site1="leg_2_r_1_s" site2="leg_2_r_2_s" solimp="0.9999 0.9999 0.001 0.1 4"/>
  </equality>

  <actuator>
    <!-- <position name="leg_1_l_1_m" joint="leg_1_l_1_h" ctrllimited="true" ctrlrange="-0.872665 0" kp="50" kv="0.1"/>
    <position name="leg_1_l_2_m" joint="leg_1_l_2_h" ctrllimited="true" ctrlrange="0 0.872665" kp="50" kv="0.1"/>
    <position name="leg_1_r_1_m" joint="leg_1_r_1_h" ctrllimited="true" ctrlrange="0 0.872665" kp="50" kv="0.1"/>
    <position name="leg_1_r_2_m" joint="leg_1_r_2_h" ctrllimited="true" ctrlrange="-0.872665 0" kp="50" kv="0.1"/> -->
    <motorfir
  </actuator>

</mujoco>
